Workbook

Sheet Dashboard
B2: VARUN BEVERAGES LIMITED — ENTERPRISE RISK DASHBOARD
B3: NSE: Varun Beverages Limited. CY2025 audited consolidated base 12 to 24 month risk horizon 24 risks across five categories five carried forward as headline risks
B5: RISKS ASSESSED | D5: CRITICAL | F5: HIGH | H5: HEADLINE RISKS | J5: SEVERE CASE PAT
B6: =COUNTA('Risk Register'!A5:A28) -> 24 | D6: =COUNTIF('Risk Register'!J5:J28,"Critical") -> 1 | F6: =COUNTIF('Risk Register'!J5:J28,"High") -> 3 | H6: =COUNT('Risk Register'!K5:K28) -> 5 | J6: ='Scenario Analysis'!N24 -> -0.49751048
B7: across five risk categories | D7: risk score 16 to 25 | F7: risk score 10 to 15 | H7: carried into report and PPT | J7: change against CY2025 actual
B9: RISK PROFILE ( ALL THE RISK ) | G9: CATEGORY EXPOSURE — number of risks by rating
B25: TOTAL RISK SCORE BY CATEGORY | G25: PROBABILITY IMPACT MATRIX
G26: ='Probability-Impact Matrix'!B5 -> IMPACT \ PROBABILITY | H26: ='Probability-Impact Matrix'!C5 -> 1 Very Low <10% | I26: ='Probability-Impact Matrix'!D5 -> 2 Low 10-29% | J26: ='Probability-Impact Matrix'!E5 -> 3 Medium 30-49% | K26: ='Probability-Impact Matrix'!F5 -> 4 High 50-69% | L26: ='Probability-Impact Matrix'!G5 -> 5 Very High >70%
G27: ='Probability-Impact Matrix'!B6 -> 5 - Severe | H27: ='Probability-Impact Matrix'!C6 -> R16* 5 | I27: ='Probability-Impact Matrix'!D6 -> 10 | J27: ='Probability-Impact Matrix'!E6 -> 15 | K27: ='Probability-Impact Matrix'!F6 -> 20 | L27: ='Probability-Impact Matrix'!G6 -> 25
G28: ='Probability-Impact Matrix'!B7 -> 4 - Major | H28: ='Probability-Impact Matrix'!C7 -> R17 4 | I28: ='Probability-Impact Matrix'!D7 -> 8 | J28: ='Probability-Impact Matrix'!E7 -> 12 | K28: ='Probability-Impact Matrix'!F7 -> R01* 16 | L28: ='Probability-Impact Matrix'!G7 -> 20
G29: ='Probability-Impact Matrix'!B8 -> 3 - Moderate | H29: ='Probability-Impact Matrix'!C8 -> 3 | I29: ='Probability-Impact Matrix'!D8 -> R10 R12 6 | J29: ='Probability-Impact Matrix'!E8 -> R05 R06 9 | K29: ='Probability-Impact Matrix'!F8 -> R02* R03* R04* 12 | L29: ='Probability-Impact Matrix'!G8 -> 15
G30: ='Probability-Impact Matrix'!B9 -> 2 - Minor | H30: ='Probability-Impact Matrix'!C9 -> R24 2 | I30: ='Probability-Impact Matrix'!D9 -> R18 R19 R20 R21 R22 R23 4 | J30: ='Probability-Impact Matrix'!E9 -> R08 R09 R11 R13 R14 R15 6 | K30: ='Probability-Impact Matrix'!F9 -> R07 8 | L30: ='Probability-Impact Matrix'!G9 -> 10
G31: ='Probability-Impact Matrix'!B10 -> 1 - Insignificant | H31: ='Probability-Impact Matrix'!C10 -> 1 | I31: ='Probability-Impact Matrix'!D10 -> 2 | J31: ='Probability-Impact Matrix'!E10 -> 3 | K31: ='Probability-Impact Matrix'!F10 -> 4 | L31: ='Probability-Impact Matrix'!G10 -> 5
B33: THE FIVE HEADLINE RISKS
B34: Rank | C34: Risk | F34: Probabiliity | G34: Impact | H34: Score | I34: Rating | J34: Recommended action
B35: 1 | C35: ='Risk Register'!C5 -> Peak-season weather variability in India | F35: ='Risk Register'!G5 -> 4 | G35: ='Risk Register'!H5 -> 4 | H35: ='Risk Register'!I5 -> 16 | I35: ='Risk Register'!J5 -> Critical | J35: ='Risk Register'!N5 -> Reduce: season-contingent production and inventory plan; track the IMD seasonal outlook as a board KRI.
B36: 2 | C36: ='Risk Register'!C6 -> Demerit fiscal treatment of carbonated drinks | F36: ='Risk Register'!G6 -> 4 | G36: ='Risk Register'!H6 -> 3 | H36: ='Risk Register'!I6 -> 12 | I36: ='Risk Register'!J6 -> High | J36: ='Risk Register'!N6 -> Reduce: accelerate the shift into lower-taxed categories; model a further rate step before pricing rounds.
B37: 3 | C37: ='Risk Register'!C7 -> Competitive intensity and price disruption in India | F37: ='Risk Register'!G7 -> 4 | G37: ='Risk Register'!H7 -> 3 | H37: ='Risk Register'!I7 -> 12 | I37: ='Risk Register'!J7 -> High | J37: ='Risk Register'!N7 -> Reduce: defend through pack-price architecture and outlet coverage; review realisation monthly.
B38: 4 | C38: ='Risk Register'!C8 -> Acquisition integration - Twizza and Bevco | F38: ='Risk Register'!G8 -> 4 | G38: ='Risk Register'!H8 -> 3 | H38: ='Risk Register'!I8 -> 12 | I38: ='Risk Register'!J8 -> High | J38: ='Risk Register'!N8 -> Reduce: 100-day integration plan with margin and working-capital milestones reported to the Board.
B39: 5 | C39: ='Risk Register'!C20 -> PepsiCo franchise concentration and renewal terms | F39: ='Risk Register'!G20 -> 1 | G39: ='Risk Register'!H20 -> 5 | H39: ='Risk Register'!I20 -> 5 | I39: ='Risk Register'!J20 -> Medium | J39: ='Risk Register'!N20 -> Retain and reduce: retain as strategically necessary; widen non-PepsiCo lines at the margin.
B41: STRESS TEST RESULTS
B42: Scenario | C42: Probability | D42: Volume (mn cases) | E42: Net revenue (Rs mn) | G42: EBITDA (Rs mn) | H42: EBITDA margin | I42: PAT (Rs mn) | K42: PAT vs CY2025
B43: CY2025 Actual | C43: ='Scenario Analysis'!C21 -> n/a | D43: ='Scenario Analysis'!E21 -> 1213.1 | E43: ='Scenario Analysis'!G21 -> 216853.79 | G43: ='Scenario Analysis'!J21 -> 50493.69 | H43: ='Scenario Analysis'!K21 -> 0.2328467 | I43: ='Scenario Analysis'!M21 -> 30620.42 | K43: ='Scenario Analysis'!N21 -> n/a
B44: Base | C44: ='Scenario Analysis'!C22 -> 0.6 | D44: ='Scenario Analysis'!E22 -> 1310.148 | E44: ='Scenario Analysis'!G22 -> 236544.11 | G44: ='Scenario Analysis'!J22 -> 55138.018 | H44: ='Scenario Analysis'!K22 -> 0.23309825 | I44: ='Scenario Analysis'!M22 -> 32981.33 | K44: ='Scenario Analysis'!N22 -> 0.077102481
B45: Adverse | C45: ='Scenario Analysis'!C23 -> 0.3 | D45: ='Scenario Analysis'!E23 -> 1237.362 | E45: ='Scenario Analysis'!G23 -> 221190.87 | G45: ='Scenario Analysis'!J23 -> 42902.78 | H45: ='Scenario Analysis'!K23 -> 0.19396271 | I45: ='Scenario Analysis'!M23 -> 23332.197 | K45: ='Scenario Analysis'!N23 -> -0.23801839
B46: Severe | C46: ='Scenario Analysis'!C24 -> 0.1 | D46: ='Scenario Analysis'!E24 -> 1176.707 | E46: ='Scenario Analysis'!G24 -> 207192.95 | G46: ='Scenario Analysis'!J24 -> 32998.061 | H46: ='Scenario Analysis'!K24 -> 0.15926247 | I46: ='Scenario Analysis'!M24 -> 15386.44 | K46: ='Scenario Analysis'!N24 -> -0.49751048
B49: KEY RISK INDICATORS — a status colour is shown only where a defensible threshold exists
B50: Risk | C50: Key risk indicator | F50: Current value | H50: Status | I50: Trigger (team threshold)
B51: R01 | C51: India volume growth, year on year | F51: +2.2% (CY2025) | H51: AMBER | I51: Below +5% for a full calendar year
B52: R03 | C52: India net realisation per case, year on year | F52: -1.5% (Q1 CY2026) | H52: RED | I52: Two consecutive quarters of decline
B53: R02 | C53: Share of volume in the 40% GST categories | F53: 73.9% (CY2025) | H53: AMBER | I53: Above 75%
B54: R04 | C54: Consolidated EBITDA margin | F54: 23.3% (CY2025) | H54: AMBER | I54: Below 22.0%
B55: R05 | C55: Material cost intensity, % of net revenue | F55: 44.8% (CY2025) | H55: GREEN | I55: Above 48%
B56: R11 | C56: Debtor days | F56: 18 days (CY2025) | H56: AMBER | I56: Above 25 days
B58: Ranking follows the risk score. PepsiCo franchise concentration is headline risk 5 through a documented strategic override: it scores low on probability because the India licence runs to 30 April 2039, but it is the only non-substitutable exposure in the register. Input-cost inflation is the highest-scoring risk outside the five. Scoring bands are team analytical thresholds; VBL discloses no risk appetite. The stress test is illustrative and is not a forecast.
B63: Risk Rating | C63: Total Risks under each category
B64: Low | C64: =COUNTIF('Risk Register'!$J$5:$J$28,B64) -> 8
B65: Medium | C65: =COUNTIF('Risk Register'!$J$5:$J$28,B65) -> 12
B66: High | C66: =COUNTIF('Risk Register'!$J$5:$J$28,B66) -> 3
B67: Critical | C67: =COUNTIF('Risk Register'!$J$5:$J$28,B67) -> 1
...

Sheet Risk Register
A1: VARUN BEVERAGES LIMITED RISK REGISTER
A4: Risk ID | B4: Risk Category | C4: Risk | D4: Type | E4: Probability | F4: Impact | G4: Probability Score | H4: Impact Score | I4: Risk Score | J4: Risk Rating | K4: Headline Risk | L4: Key Cause | M4: Existing Control (VBL) | N4: Response Action (team)
A5: R01 | B5: Climate & Environment | C5: Peak-season weather variability in India | D5: External | E5: High | F5: Major | G5: =VLOOKUP(E5,$B$33:$E$37,4,0) -> 4 | H5: =VLOOKUP(F5,$B$41:$E$45,4,0) -> 4 | I5: =G5*H5 -> 16 | J5: =VLOOKUP(I5,$B$49:$D$52,2,TRUE()) -> Critical | K5: 1 | L5: Unseasonal and early monsoon rain in the April-June quarter, when most annual volume is sold. | M5: Spread across 10 franchise countries; CSD, NCB and water portfolio; cold-chain and visi-cooler reach. | N5: Reduce: season-contingent production and inventory plan; track the IMD seasonal outlook as a board KRI.
A6: R02 | B6: Regulatory & Compliance | C6: Demerit fiscal treatment of carbonated drinks | D6: External | E6: High | F6: Moderate | G6: =VLOOKUP(E6,$B$33:$E$37,4,0) -> 4 | H6: =VLOOKUP(F6,$B$41:$E$45,4,0) -> 3 | I6: =G6*H6 -> 12 | J6: =VLOOKUP(I6,$B$49:$D$52,2,TRUE()) -> High | K6: 2 | L6: CSD and caffeinated drinks sit in the 40% GST slab from 22 Sep 2025, previously 28% plus 12% cess. | M6: Mix shift into water and juice, which moved to 5% GST; engagement with government alongside PepsiCo. | N6: Reduce: accelerate the shift into lower-taxed categories; model a further rate step before pricing rounds.
A7: R03 | B7: Financial & Market | C7: Competitive intensity and price disruption in India | D7: External | E7: High | F7: Moderate | G7: =VLOOKUP(E7,$B$33:$E$37,4,0) -> 4 | H7: =VLOOKUP(F7,$B$41:$E$45,4,0) -> 3 | I7: =G7*H7 -> 12 | J7: =VLOOKUP(I7,$B$49:$D$52,2,TRUE()) -> High | K7: 3 | L7: A well-funded entrant at aggressive price points and a recapitalised competing bottling system. | M7: Distribution depth and visi-cooler placement; pack-price architecture; PepsiCo brand support. | N7: Reduce: defend through pack-price architecture and outlet coverage; review realisation monthly.
A8: R04 | B8: Strategic & International | C8: Acquisition integration - Twizza and Bevco | D8: Internal | E8: High | F8: Moderate | G8: =VLOOKUP(E8,$B$33:$E$37,4,0) -> 4 | H8: =VLOOKUP(F8,$B$41:$E$45,4,0) -> 3 | I8: =G8*H8 -> 12 | J8: =VLOOKUP(I8,$B$49:$D$52,2,TRUE()) -> High | K8: 4 | L8: Twizza bought for ZAR 2,095 mn EV and consolidated during CY2026 at a lower margin than the group. | M8: Board acquisition guidelines; dedicated integration effort for newly acquired territories. | N8: Reduce: 100-day integration plan with margin and working-capital milestones reported to the Board.
A9: R05 | B9: Financial & Market | C9: Input-cost inflation in sugar, aluminium and PET | D9: External | E9: Medium | F9: Moderate | G9: =VLOOKUP(E9,$B$33:$E$37,4,0) -> 3 | H9: =VLOOKUP(F9,$B$41:$E$45,4,0) -> 3 | I9: =G9*H9 -> 9 | J9: =VLOOKUP(I9,$B$49:$D$52,2,TRUE()) -> Medium | L9: Materials were Rs 97,154 mn, 44.8% of CY2025 net revenue, across policy-driven commodity markets. | M9: Backward integration into preforms, crowns, closures and boxes; consolidated sourcing; scale buying. | N9: Retain: controls are holding gross margin; monitor material cost intensity monthly.
A10: R06 | B10: Strategic & International | C10: Utilisation of the four new India greenfield plants | D10: Internal | E10: Medium | F10: Moderate | G10: =VLOOKUP(E10,$B$33:$E$37,4,0) -> 3 | H10: =VLOOKUP(F10,$B$41:$E$45,4,0) -> 3 | I10: =G10*H10 -> 9 | J10: =VLOOKUP(I10,$B$49:$D$52,2,TRUE()) -> Medium | L10: Rs 17,000 mn spent on four greenfields while India volume grew only 2.2% in CY2025. | M10: Contiguous-territory strategy; capex funded from operating cash flow rather than debt. | N10: Reduce: report plant-level utilisation against plan before sanctioning further India greenfields.
A11: R07 | B11: Strategic & International | C11: Currency translation exposure on international earnings | D11: External | E11: High | F11: Minor | G11: =VLOOKUP(E11,$B$33:$E$37,4,0) -> 4 | H11: =VLOOKUP(F11,$B$41:$E$45,4,0) -> 2 | I11: =G11*H11 -> 8 | J11: =VLOOKUP(I11,$B$49:$D$52,2,TRUE()) -> Medium | L11: 36.4% of CY2025 contract revenue is earned outside India in African and South Asian currencies. | M11: Local-currency operating model with local sourcing; natural hedge of revenue against local cost. | N11: Retain: accept translation exposure as the cost of diversification; hedge identified transactions only.
A12: R08 | B12: Strategic & International | C12: New-territory entry and non-PepsiCo lines | D12: Internal | E12: Medium | F12: Minor | G12: =VLOOKUP(E12,$B$33:$E$37,4,0) -> 3 | H12: =VLOOKUP(F12,$B$41:$E$45,4,0) -> 2 | I12: =G12*H12 -> 6 | J12: =VLOOKUP(I12,$B$49:$D$52,2,TRUE()) -> Medium | L12: Kenya subsidiary, Carlsberg distribution and PepsiCo snacks in Zimbabwe and Zambia started recently. | M12: Staged entry using existing distribution; Board acquisition guidelines applied to each new line. | N12: Reduce: set a margin gate for each new line before committing further capital.
A13: R09 | B13: Strategic & International | C13: Country and political risk in African territories | D13: External | E13: Medium | F13: Minor | G13: =VLOOKUP(E13,$B$33:$E$37,4,0) -> 3 | H13: =VLOOKUP(F13,$B$41:$E$45,4,0) -> 2 | I13: =G13*H13 -> 6 | J13: =VLOOKUP(I13,$B$49:$D$52,2,TRUE()) -> Medium | L13: Operations across territories with variable power, water and security conditions. | M13: Spread across 10 franchise countries so no single territory dominates; local management teams. | N13: Retain: monitor territory performance quarterly; no single-country concentration above plan.
A14: R10 | B14: Operations & Supply Chain | C14: Raw material and packaging supply interruption | D14: External | E14: Low | F14: Moderate | G14: =VLOOKUP(E14,$B$33:$E$37,4,0) -> 2 | H14: =VLOOKUP(F14,$B$41:$E$45,4,0) -> 3 | I14: =G14*H14 -> 6 | J14: =VLOOKUP(I14,$B$49:$D$52,2,TRUE()) -> Medium | L14: Concentrated supply of concentrate, resin, closures and aluminium into a seasonal production peak. | M14: Backward integration for preforms, crowns, closures and corrugated boxes; alternative sources developed. | N14: Reduce: hold pre-season safety stock of critical inputs and qualify a second source for each.
A15: R11 | B15: Financial & Market | C15: Receivables and working-capital stretch | D15: Internal | E15: Medium | F15: Minor | G15: =VLOOKUP(E15,$B$33:$E$37,4,0) -> 3 | H15: =VLOOKUP(F15,$B$41:$E$45,4,0) -> 2 | I15: =G15*H15 -> 6 | J15: =VLOOKUP(I15,$B$49:$D$52,2,TRUE()) -> Medium | L15: Debtor days rose from 11 to 18 in CY2025 on a higher modern-trade mix in South Africa. | M15: Credit assessment of distributors; provisioning discipline; scale-based supplier terms. | N15: Reduce: tighten modern-trade credit terms and report debtor days monthly.
A16: R12 | B16: Strategic & International | C16: Capital allocation discipline | D16: Internal | E16: Low | F16: Moderate | G16: =VLOOKUP(E16,$B$33:$E$37,4,0) -> 2 | H16: =VLOOKUP(F16,$B$41:$E$45,4,0) -> 3 | I16: =G16*H16 -> 6 | J16: =VLOOKUP(I16,$B$49:$D$52,2,TRUE()) -> Medium | L16: About Rs 45,000 mn capitalised in CY2025 alongside acquisitions in a single year. | M16: Board-approved acquisition guidelines; internal funding; India business remains net debt-free. | N16: Reduce: apply a return hurdle and post-completion review to every project above a set size.
A17: R13 | B17: Regulatory & Compliance | C17: Health labelling and consumer-health regulation | D17: External | E17: Medium | F17: Minor | G17: =VLOOKUP(E17,$B$33:$E$37,4,0) -> 3 | H17: =VLOOKUP(F17,$B$41:$E$45,4,0) -> 2 | I17: =G17*H17 -> 6 | J17: =VLOOKUP(I17,$B$49:$D$52,2,TRUE()) -> Medium | L17: Front-of-pack nutrition labelling for high sugar products is under development in India. | M17: PepsiCo zero-sugar and low-calorie portfolio; continuous review of consumer habits with PepsiCo. | N17: Reduce: prepare labelling-compliant artwork and reformulation ahead of notification.
A18: R14 | B18: Regulatory & Compliance | C18: Packaging EPR and recycled-content cost | D18: External | E18: Medium | F18: Minor | G18: =VLOOKUP(E18,$B$33:$E$37,4,0) -> 3 | H18: =VLOOKUP(F18,$B$41:$E$45,4,0) -> 2 | I18: =G18*H18 -> 6 | J18: =VLOOKUP(I18,$B$49:$D$52,2,TRUE()) -> Medium | L18: A rising statutory recycled-content obligation for rigid plastic and food-contact PET. | M18: GEM Enviro collection and recycling partnership; stated 30% rPET target in total plastic use. | N18: Reduce: contract multi-year food-grade rPET supply ahead of each step-up in the mandate.
A19: R15 | B19: Operations & Supply Chain | C19: Labour cost and industrial relations | D19: Internal | E19: Medium | F19: Minor | G19: =VLOOKUP(E19,$B$33:$E$37,4,0) -> 3 | H19: =VLOOKUP(F19,$B$41:$E$45,4,0) -> 2 | I19: =G19*H19 -> 6 | J19: =VLOOKUP(I19,$B$49:$D$52,2,TRUE()) -> Medium | L19: Over 16,300 employees and the notification of India's four Labour Codes. | M19: Recruitment, appraisal, training and welfare policies; second-level cover in each department. | N19: Retain: the cost is recurring and already absorbed in the CY2025 base.
A20: R16 | B20: Strategic & International | C20: PepsiCo franchise concentration and renewal terms | D20: External | E20: Very Low | F20: Severe | G20: =VLOOKUP(E20,$B$33:$E$37,4,0) -> 1 | H20: =VLOOKUP(F20,$B$41:$E$45,4,0) -> 5 | I20: =G20*H20 -> 5 | J20: =VLOOKUP(I20,$B$49:$D$52,2,TRUE()) -> Medium | K20: 5 | L20: The entire India portfolio is licensed from PepsiCo and VBL is over 90% of PepsiCo's India volumes. | M20: India licence extended to 30 April 2039; mutual dependence; joint investment and business planning. | N20: Retain and reduce: retain as strategically necessary; widen non-PepsiCo lines at the margin.
A21: R17 | B21: Operations & Supply Chain | C21: Product safety and recall | D21: Internal | E21: Very Low | F21: Major | G21: =VLOOKUP(E21,$B$33:$E$37,4,0) -> 1 | H21: =VLOOKUP(F21,$B$41:$E$45,4,0) -> 4 | I21: =G21*H21 -> 4 | J21: =VLOOKUP(I21,$B$49:$D$52,2,TRUE()) -> Low | L21: 50 plants across 14 countries producing beverages for direct human consumption. | M21: PepsiCo global quality standards and audits; food safety management systems and certification. | N21: Reduce and transfer: maintain the audit regime and carry product-liability cover.
A22: R18 | B22: Financial & Market | C22: Consumer preference shift away from sugar CSDs | D22: External | E22: Low | F22: Minor | G22: =VLOOKUP(E22,$B$33:$E$37,4,0) -> 2 | H22: =VLOOKUP(F22,$B$41:$E$45,4,0) -> 2 | I22: =G22*H22 -> 4 | J22: =VLOOKUP(I22,$B$49:$D$52,2,TRUE()) -> Low | L22: Rising health awareness against a portfolio that is 73.9% carbonated by volume. | M22: PepsiCo zero-sugar and low-calorie range; NCB and packaged water expansion. | N22: Reduce: continue reformulation and NCB expansion so the shift is led rather than followed.
A23: R19 | B23: Climate & Environment | C23: Water availability and groundwater regulation | D23: External | E23: Low | F23: Minor | G23: =VLOOKUP(E23,$B$33:$E$37,4,0) -> 2 | H23: =VLOOKUP(F23,$B$41:$E$45,4,0) -> 2 | I23: =G23*H23 -> 4 | J23: =VLOOKUP(I23,$B$49:$D$52,2,TRUE()) -> Low | L23: Water-intensive manufacturing with Indian plants in over-exploited and critical CGWA blocks. | M23: Over 300 water bodies adopted and 150+ water-efficiency improvements; rainwater harvesting. | N23: Reduce: hold replenishment above abstraction and maintain valid consents at every site.
A24: R20 | B24: Climate & Environment | C24: Carbon, energy and emissions regulation | D24: External | E24: Low | F24: Minor | G24: =VLOOKUP(E24,$B$33:$E$37,4,0) -> 2 | H24: =VLOOKUP(F24,$B$41:$E$45,4,0) -> 2 | I24: =G24*H24 -> 4 | J24: =VLOOKUP(I24,$B$49:$D$52,2,TRUE()) -> Low | L24: Energy-intensive cooling and logistics against a stated net-zero-by-2050 target from a 2023 base. | M24: Solar installations across territories; energy-efficiency programmes; lighter packaging grammage. | N24: Reduce: hold the renewable and efficiency programme to its schedule and report progress annually.
A25: R21 | B25: Operations & Supply Chain | C25: Distribution and route-to-market execution | D25: Internal | E25: Low | F25: Minor | G25: =VLOOKUP(E25,$B$33:$E$37,4,0) -> 2 | H25: =VLOOKUP(F25,$B$41:$E$45,4,0) -> 2 | I25: =G25*H25 -> 4 | J25: =VLOOKUP(I25,$B$49:$D$52,2,TRUE()) -> Low | L25: Contracted logistics and a distributor-led route to market across urban, semi-urban and rural India. | M25: Owned cold-chain and visi-cooler network; distributor consolidation; logistics policy measures. | N25: Reduce: tighten peak-season distributor stocking norms and monitor fill rates.
A26: R22 | B26: Operations & Supply Chain | C26: Cold-chain and visi-cooler reliability | D26: Internal | E26: Low | F26: Minor | G26: =VLOOKUP(E26,$B$33:$E$37,4,0) -> 2 | H26: =VLOOKUP(F26,$B$41:$E$45,4,0) -> 2 | I26: =G26*H26 -> 4 | J26: =VLOOKUP(I26,$B$49:$D$52,2,TRUE()) -> Low | L26: Chilled availability depends on visi-coolers and power reliability in under-penetrated markets. | M26: Continued visi-cooler deployment; White Peak refrigeration joint venture for in-house manufacture. | N26: Reduce: prioritise servicing and replacement in high-throughput outlets before each season.
A27: R23 | B27: Operations & Supply Chain | C27: IT and cyber security | D27: Internal | E27: Low | F27: Minor | G27: =VLOOKUP(E27,$B$33:$E$37,4,0) -> 2 | H27: =VLOOKUP(F27,$B$41:$E$45,4,0) -> 2 | I27: =G27*H27 -> 4 | J27: =VLOOKUP(I27,$B$49:$D$52,2,TRUE()) -> Low | L27: Digitised production scheduling, sales and distribution systems across 14 countries. | M27: Access control, multi-factor authentication, firewalls, threat detection, backups and awareness training. | N27: Reduce: maintain the control set and test recovery through periodic drills.
A28: R24 | B28: Financial & Market | C28: Funding, interest rate and liquidity | D28: Internal | E28: Very Low | F28: Minor | G28: =VLOOKUP(E28,$B$33:$E$37,4,0) -> 1 | H28: =VLOOKUP(F28,$B$41:$E$45,4,0) -> 2 | I28: =G28*H28 -> 2 | J28: =VLOOKUP(I28,$B$49:$D$52,2,TRUE()) -> Low | L28: Capex and acquisition funding alongside pronounced seasonal working-capital swings. | M28: India net debt-free with free cash of ~Rs 12,250 mn; consolidated net debt ~Rs 256 mn; CRISIL AAA. | N28: Retain: exposure is immaterial relative to current cash generation.
B31: PROBABILITY SCALE (1-5)
B32: Probability | D32: Chance of occurring within 12 to 24 months | E32: Score
B33: Very Low | D33: Less than 10% | E33: 1
B34: Low | D34: 10% to 29% | E34: 2
B35: Medium | D35: 30% to 49% | E35: 3
B36: High | D36: 50% to 69% | E36: 4
B37: Very High | D37: More than 70% | E37: 5
B39: IMPACT SCALE (1-5)
B40: Impact | D40: Adverse effect on annual EBITDA | E40: Score
B41: Insignificant | D41: Below Rs 250 mn (under 0.5% of EBITDA) | E41: 1
B42: Minor | D42: Rs 250 to 1,000 mn (0.5% to 2%) | E42: 2
B43: Moderate | D43: Rs 1,000 to 2,500 mn (2% to 5%) | E43: 3
B44: Major | D44: Rs 2,500 to 5,000 mn (5% to 10%) | E44: 4
B45: Severe | D45: Above Rs 5,000 mn (over 10%) | E45: 5
...

Sheet Probability-Impact Matrix
B2: PROBABILITY - IMPACT MATRIX — ALL 24 RISKS
B3: Cell shading follows the rating bands on the Risk Register. * marks a headline risk.
B5: IMPACT \ PROBABILITY | C5: 1 Very Low <10% | D5: 2 Low 10-29% | E5: 3 Medium 30-49% | F5: 4 High 50-69% | G5: 5 Very High >70%
B6: 5 - Severe | C6: R16* 5 | D6: 10 | E6: 15 | F6: 20 | G6: 25
B7: 4 - Major | C7: R17 4 | D7: 8 | E7: 12 | F7: R01* 16 | G7: 20
B8: 3 - Moderate | C8: 3 | D8: R10 R12 6 | E8: R05 R06 9 | F8: R02* R03* R04* 12 | G8: 15
B9: 2 - Minor | C9: R24 2 | D9: R18 R19 R20 R21 R22 R23 4 | E9: R08 R09 R11 R13 R14 R15 6 | F9: R07 8 | G9: 10
B10: 1 - Insignificant | C10: 1 | D10: 2 | E10: 3 | F10: 4 | G10: 5
B12: LEGEND — linked to the Risk Register
B13: Risk ID | C13: Risk | D13: Probability | E13: Impact | F13: Risk Score | G13: Risk Rating
B14: ='Risk Register'!A5 -> R01 | C14: ='Risk Register'!C5 -> Peak-season weather variability in India | D14: ='Risk Register'!G5 -> 4 | E14: ='Risk Register'!H5 -> 4 | F14: ='Risk Register'!I5 -> 16 | G14: ='Risk Register'!J5 -> Critical
B15: ='Risk Register'!A6 -> R02 | C15: ='Risk Register'!C6 -> Demerit fiscal treatment of carbonated drinks | D15: ='Risk Register'!G6 -> 4 | E15: ='Risk Register'!H6 -> 3 | F15: ='Risk Register'!I6 -> 12 | G15: ='Risk Register'!J6 -> High
B16: ='Risk Register'!A7 -> R03 | C16: ='Risk Register'!C7 -> Competitive intensity and price disruption in India | D16: ='Risk Register'!G7 -> 4 | E16: ='Risk Register'!H7 -> 3 | F16: ='Risk Register'!I7 -> 12 | G16: ='Risk Register'!J7 -> High
B17: ='Risk Register'!A8 -> R04 | C17: ='Risk Register'!C8 -> Acquisition integration - Twizza and Bevco | D17: ='Risk Register'!G8 -> 4 | E17: ='Risk Register'!H8 -> 3 | F17: ='Risk Register'!I8 -> 12 | G17: ='Risk Register'!J8 -> High
B18: ='Risk Register'!A9 -> R05 | C18: ='Risk Register'!C9 -> Input-cost inflation in sugar, aluminium and PET | D18: ='Risk Register'!G9 -> 3 | E18: ='Risk Register'!H9 -> 3 | F18: ='Risk Register'!I9 -> 9 | G18: ='Risk Register'!J9 -> Medium
B19: ='Risk Register'!A10 -> R06 | C19: ='Risk Register'!C10 -> Utilisation of the four new India greenfield plants | D19: ='Risk Register'!G10 -> 3 | E19: ='Risk Register'!H10 -> 3 | F19: ='Risk Register'!I10 -> 9 | G19: ='Risk Register'!J10 -> Medium
B20: ='Risk Register'!A11 -> R07 | C20: ='Risk Register'!C11 -> Currency translation exposure on international earnings | D20: ='Risk Register'!G11 -> 4 | E20: ='Risk Register'!H11 -> 2 | F20: ='Risk Register'!I11 -> 8 | G20: ='Risk Register'!J11 -> Medium
B21: ='Risk Register'!A12 -> R08 | C21: ='Risk Register'!C12 -> New-territory entry and non-PepsiCo lines | D21: ='Risk Register'!G12 -> 3 | E21: ='Risk Register'!H12 -> 2 | F21: ='Risk Register'!I12 -> 6 | G21: ='Risk Register'!J12 -> Medium
B22: ='Risk Register'!A13 -> R09 | C22: ='Risk Register'!C13 -> Country and political risk in African territories | D22: ='Risk Register'!G13 -> 3 | E22: ='Risk Register'!H13 -> 2 | F22: ='Risk Register'!I13 -> 6 | G22: ='Risk Register'!J13 -> Medium
B23: ='Risk Register'!A14 -> R10 | C23: ='Risk Register'!C14 -> Raw material and packaging supply interruption | D23: ='Risk Register'!G14 -> 2 | E23: ='Risk Register'!H14 -> 3 | F23: ='Risk Register'!I14 -> 6 | G23: ='Risk Register'!J14 -> Medium
B24: ='Risk Register'!A15 -> R11 | C24: ='Risk Register'!C15 -> Receivables and working-capital stretch | D24: ='Risk Register'!G15 -> 3 | E24: ='Risk Register'!H15 -> 2 | F24: ='Risk Register'!I15 -> 6 | G24: ='Risk Register'!J15 -> Medium
B25: ='Risk Register'!A16 -> R12 | C25: ='Risk Register'!C16 -> Capital allocation discipline | D25: ='Risk Register'!G16 -> 2 | E25: ='Risk Register'!H16 -> 3 | F25: ='Risk Register'!I16 -> 6 | G25: ='Risk Register'!J16 -> Medium
... B37: ='Risk Register'!A28 -> R24 | C37: ='Risk Register'!C28 -> Funding, interest rate and liquidity | D37: ='Risk Register'!G28 -> 1 | E37: ='Risk Register'!H28 -> 2 | F37: ='Risk Register'!I28 -> 2 | G37: ='Risk Register'!J28 -> Low

Sheet Scenario Analysis
B2: ILLUSTRATIVE STRESS TEST — BASED ON TEAM ASSUMPTIONS
B3: Note : Not a forecast and not VBL guidance. Blue figures are the only inputs; every other figure is calculated. CY2025 audited consolidated actuals are the base.
B5: 1. CY2025 AUDITED BASE ACTUALS
B6: Line | E6: Value | F6: Source
B7: Total sales volume (mn cases) | E7: 1213.1 | F7: AR CY2025 MD&A: India 839 + international 374
B8: Net revenue (Rs mn) | E8: 216853.79 | F8: AR CY2025 MD&A: revenue from operations less excise duty
B9: Net realisation per case (Rs) | E9: =E8/E7 -> 178.76003 | F9: Calculated. AR states Rs 178.8
B10: Materials consumed (Rs mn) | E10: 97154.29 | F10: AR CY2025 P&L: 93,370.62 + 3,694.53 + 89.14
B11: Gross margin % | E11: =(E8-E10)/E8 -> 0.55198251 | F11: Calculated. AR states 55.2%
B12: Employee and other operating cost (Rs mn) | E12: 69205.81 | F12: AR CY2025 P&L: 22,007.43 + 47,198.38
B13: EBITDA (Rs mn) | E13: =E8-E10-E12 -> 50493.69 | F13: Calculated. AR states Rs 50,493.69 mn
B14: EBITDA margin % | E14: =E13/E8 -> 0.2328467 | F14: Calculated. AR states 23.3%
B15: Non-EBITDA items, net (Rs mn) | E15: 10397.21 | F15: D&A 12,164.63 + finance 1,695.79 - other income 3,523.48 + share of loss 60.27
B16: Effective tax rate % | E16: 0.23633147 | F16: AR CY2025 P&L: tax 9,476.06 / PBT 40,096.48
B17: Profit after tax (Rs mn) | E17: =(E13-E15)*(1-E16) -> 30620.42 | F17: Calculated. AR states Rs 30,620.42 mn
B19: 2. SCENARIO MODEL — blue cells are team assumptions
B20: Scenario | C20: Probability of scenario | D20: Volume growth % | E20: Volume (mn cases) | F20: Realisation growth % | G20: Net revenue (Rs mn) | H20: Gross margin % | I20: Op cost growth % | J20: EBITDA (Rs mn) | K20: EBITDA margin % | L20: Non-EBITDA items (Rs mn) | M20: PAT (Rs mn) | N20: PAT vs CY2025
B21: CY2025 Actual | C21: n/a | D21: n/a | E21: =$E$7 -> 1213.1 | F21: n/a | G21: =$E$8 -> 216853.79 | H21: =$E$11 -> 0.55198251 | I21: n/a | J21: =$E$13 -> 50493.69 | K21: =$E$14 -> 0.2328467 | L21: =$E$15 -> 10397.21 | M21: =$E$17 -> 30620.42 | N21: n/a
B22: Base | C22: 0.6 | D22: 0.08 | E22: =$E$7*(1+D22) -> 1310.148 | F22: 0.01 | G22: =E22*($E$9*(1+F22)) -> 236544.11 | H22: 0.552 | I22: 0.09 | J22: =G22*H22-$E$12*(1+I22) -> 55138.018 | K22: =J22/G22 -> 0.23309825 | L22: 11950 | M22: =(J22-L22)*(1-$E$16) -> 32981.33 | N22: =M22/$E$17-1 -> 0.077102481
B23: Adverse | C23: 0.3 | D23: 0.02 | E23: =$E$7*(1+D23) -> 1237.362 | F23: 0 | G23: =E23*($E$9*(1+F23)) -> 221190.87 | H23: 0.535 | I23: 0.09 | J23: =G23*H23-$E$12*(1+I23) -> 42902.78 | K23: =J23/G23 -> 0.19396271 | L23: 12350 | M23: =(J23-L23)*(1-$E$16) -> 23332.197 | N23: =M23/$E$17-1 -> -0.23801839
B24: Severe | C24: 0.1 | D24: -0.03 | E24: =$E$7*(1+D24) -> 1176.707 | F24: -0.015 | G24: =E24*($E$9*(1+F24)) -> 207192.95 | H24: 0.52 | I24: 0.08 | J24: =G24*H24-$E$12*(1+I24) -> 32998.061 | K24: =J24/G24 -> 0.15926247 | L24: 12850 | M24: =(J24-L24)*(1-$E$16) -> 15386.44 | N24: =M24/$E$17-1 -> -0.49751048
B25: How to read: volume x realisation = net revenue; net revenue x gross margin - operating cost = EBITDA; EBITDA - Non EBITDA items (taxed)= PAT. Operating cost is set as a growth rate rather than a variable cost because most employee and other operating expense does not fall when volume falls, which is why margin compresses faster than revenue in the adverse and severe cases. Gross margin is the single largest lever in the severe case.

Sheet Sources & Assumptions
B2: SOURCES, EVIDENCE GRADES AND TEAM ASSUMPTIONS
B3: Grade A = VBL primary. B = official external (regulator or government). C = authoritative external. D = team inference. E = team assumption.
B5: Item | C5: Value used | D5: Source | E5: Grade | F5: Note
B6: Net revenue CY2025 | C6: Rs 216,853.79 mn | D6: VBL Annual Report CY2025, MD&A | E6: A | F6: Revenue from operations 222,255.84 less excise duty 5,402.05. The Ind AS 115 note shows 213,748.09 because it is net of discounts and rebates; the P&L figure is used throughout.
B7: EBITDA CY2025 | C7: Rs 50,493.69 mn | D7: VBL Annual Report CY2025, MD&A | E7: A | F7: Anchor for the 1-5 impact scale.
B8: PAT CY2025 | C8: Rs 30,620.42 mn | D8: VBL Annual Report CY2025, MD&A | E8: A | F8: Base for the PAT change column in the stress test.
B9: Total sales volume CY2025 | C9: 1,213.1 mn cases | D9: VBL Annual Report CY2025, MD&A | E9: A | F9: India 839, international 374.
B10: Net realisation per case CY2025 | C10: Rs 178.8 | D10: VBL Annual Report CY2025, MD&A | E10: A | F10: Calculated in the model as net revenue divided by volume.
B11: Gross margin CY2025 | C11: 55.2% | D11: VBL Annual Report CY2025, MD&A | E11: A | F11: CY2024 was 55.5%. Evidence that input-cost controls are working (R05).
B12: India revenue CY2025 | C12: Rs 136,045.62 mn | D12: VBL AR CY2025, Ind AS 115 geography note | E12: A | F12: CY2024 was 136,173.93, so India revenue was flat. Central evidence for R01.
B13: Revenue outside India CY2025 | C13: Rs 77,702.47 mn | D13: VBL AR CY2025, Ind AS 115 geography note | E13: A | F13: CY2024 63,013.31, up 23.3%. 36.4% of contract revenue. Evidence for R07 and R09.
B14: Volume mix CY2025 | C14: CSD 73.9%, NCB 5.9%, water 20.2% | D14: VBL Annual Report CY2025, MD&A | E14: A | F14: Basis for the R02 exposure statement.
B15: Q2 CY2025 India volume | C15: Fell 7.1% | D15: VBL quarterly results, Q2 CY2025 | E15: A | F15: The realised weather event behind the R01 probability score.
B16: India volume growth CY2025 | C16: +2.2% (839 from 821 mn cases) | D16: VBL Annual Report CY2025, MD&A | E16: A | F16: Basis for the R01 impact estimate and for R06.
... B36: Scenario drivers | C36: Scenario Analysis, blue cells in rows 22 to 24 | D36: Team assumption | E36: E | F36: Probability of scenario, volume growth, realisation growth, gross margin, operating cost growth and non-EBITDA items. Not a forecast and not VBL guidance.
